[2022-09-15 16:24:11,720] {taskinstance.py:1179} INFO - Dependencies all met for <TaskInstance: preprocessing_data.validate_model scheduled__2022-09-15T15:54:58.361746+00:00 [queued]>
[2022-09-15 16:24:11,725] {taskinstance.py:1179} INFO - Dependencies all met for <TaskInstance: preprocessing_data.validate_model scheduled__2022-09-15T15:54:58.361746+00:00 [queued]>
[2022-09-15 16:24:11,725] {taskinstance.py:1376} INFO - 
--------------------------------------------------------------------------------
[2022-09-15 16:24:11,725] {taskinstance.py:1377} INFO - Starting attempt 1 of 2
[2022-09-15 16:24:11,725] {taskinstance.py:1378} INFO - 
--------------------------------------------------------------------------------
[2022-09-15 16:24:11,739] {taskinstance.py:1397} INFO - Executing <Task(PythonOperator): validate_model> on 2022-09-15 15:54:58.361746+00:00
[2022-09-15 16:24:11,745] {standard_task_runner.py:52} INFO - Started process 69420 to run task
[2022-09-15 16:24:11,749] {standard_task_runner.py:79} INFO - Running: ['airflow', 'tasks', 'run', 'preprocessing_data', 'validate_model', 'scheduled__2022-09-15T15:54:58.361746+00:00', '--job-id', '299', '--raw', '--subdir', 'DAGS_FOLDER/model_dag.py', '--cfg-path', '/tmp/tmprwsrf3px', '--error-file', '/tmp/tmp8ay012kl']
[2022-09-15 16:24:11,749] {standard_task_runner.py:80} INFO - Job 299: Subtask validate_model
[2022-09-15 16:24:11,800] {task_command.py:371} INFO - Running <TaskInstance: preprocessing_data.validate_model scheduled__2022-09-15T15:54:58.361746+00:00 [running]> on host rc1b-dataproc-m-xzxwmqcudfo0foh0.mdb.yandexcloud.net
[2022-09-15 16:24:11,861] {taskinstance.py:1589} INFO - Exporting the following env vars:
AIRFLOW_CTX_DAG_EMAIL=airflow@example.com
AIRFLOW_CTX_DAG_OWNER=airflow
AIRFLOW_CTX_DAG_ID=preprocessing_data
AIRFLOW_CTX_TASK_ID=validate_model
AIRFLOW_CTX_EXECUTION_DATE=2022-09-15T15:54:58.361746+00:00
AIRFLOW_CTX_TRY_NUMBER=1
AIRFLOW_CTX_DAG_RUN_ID=scheduled__2022-09-15T15:54:58.361746+00:00
[2022-09-15 16:24:27,165] {logging_mixin.py:115} WARNING - 2022/09/15 16:24:27 INFO mlflow.spark: 'runs:/36cadb49eedf45a0bdb4bbc8c4159f72/model' resolved as 's3://otus-bigdata-dima-ioksha/1/36cadb49eedf45a0bdb4bbc8c4159f72/artifacts/model'
[2022-09-15 16:24:27,238] {credentials.py:1094} INFO - Found credentials in environment variables.
[2022-09-15 16:24:27,462] {taskinstance.py:1909} ERROR - Task failed with exception
Traceback (most recent call last):
  File "/home/ubuntu/.local/lib/python3.8/site-packages/mlflow/utils/model_utils.py", line 58, in _get_flavor_configuration_from_uri
    ml_model_file = _download_artifact_from_uri(
  File "/home/ubuntu/.local/lib/python3.8/site-packages/mlflow/tracking/artifact_utils.py", line 100, in _download_artifact_from_uri
    return get_artifact_repository(artifact_uri=root_uri).download_artifacts(
  File "/home/ubuntu/.local/lib/python3.8/site-packages/mlflow/store/artifact/artifact_repo.py", line 263, in download_artifacts
    raise MlflowException(
mlflow.exceptions.MlflowException: The following failures occurred while downloading one or more artifacts from s3://otus-bigdata-dima-ioksha/1/36cadb49eedf45a0bdb4bbc8c4159f72/artifacts/model: {'MLmodel': "ClientError('An error occurred (404) when calling the HeadObject operation: Not Found')"}

During handling of the above exception, another exception occurred:

Traceback (most recent call last):
  File "/home/ubuntu/.local/lib/python3.8/site-packages/airflow/operators/python.py", line 171, in execute
    return_value = self.execute_callable()
  File "/home/ubuntu/.local/lib/python3.8/site-packages/airflow/operators/python.py", line 189, in execute_callable
    return self.python_callable(*self.op_args, **self.op_kwargs)
  File "/home/ubuntu/fraud-detection-ml/utils/validate_model.py", line 32, in validate_model
    model = mlflow.spark.load_model(f"runs:/{run_id}/model")
  File "/home/ubuntu/.local/lib/python3.8/site-packages/mlflow/spark.py", line 772, in load_model
    flavor_conf = _get_flavor_configuration_from_uri(model_uri, FLAVOR_NAME)
  File "/home/ubuntu/.local/lib/python3.8/site-packages/mlflow/utils/model_utils.py", line 62, in _get_flavor_configuration_from_uri
    raise MlflowException(
mlflow.exceptions.MlflowException: Failed to download an "MLmodel" model file from "s3://otus-bigdata-dima-ioksha/1/36cadb49eedf45a0bdb4bbc8c4159f72/artifacts/model": The following failures occurred while downloading one or more artifacts from s3://otus-bigdata-dima-ioksha/1/36cadb49eedf45a0bdb4bbc8c4159f72/artifacts/model: {'MLmodel': "ClientError('An error occurred (404) when calling the HeadObject operation: Not Found')"}
[2022-09-15 16:24:27,466] {taskinstance.py:1415} INFO - Marking task as UP_FOR_RETRY. dag_id=preprocessing_data, task_id=validate_model, execution_date=20220915T155458, start_date=20220915T162411, end_date=20220915T162427
[2022-09-15 16:24:27,478] {standard_task_runner.py:92} ERROR - Failed to execute job 299 for task validate_model (Failed to download an "MLmodel" model file from "s3://otus-bigdata-dima-ioksha/1/36cadb49eedf45a0bdb4bbc8c4159f72/artifacts/model": The following failures occurred while downloading one or more artifacts from s3://otus-bigdata-dima-ioksha/1/36cadb49eedf45a0bdb4bbc8c4159f72/artifacts/model: {'MLmodel': "ClientError('An error occurred (404) when calling the HeadObject operation: Not Found')"}; 69420)
[2022-09-15 16:24:27,522] {local_task_job.py:156} INFO - Task exited with return code 1
[2022-09-15 16:24:27,532] {local_task_job.py:273} INFO - 0 downstream tasks scheduled from follow-on schedule check
