[2022-06-26 13:43:09,201] {taskinstance.py:1159} INFO - Dependencies all met for <TaskInstance: fraud_generation.generate_transaction scheduled__2022-06-26T13:33:04.519575+00:00 [queued]>
[2022-06-26 13:43:09,216] {taskinstance.py:1159} INFO - Dependencies all met for <TaskInstance: fraud_generation.generate_transaction scheduled__2022-06-26T13:33:04.519575+00:00 [queued]>
[2022-06-26 13:43:09,216] {taskinstance.py:1356} INFO - 
--------------------------------------------------------------------------------
[2022-06-26 13:43:09,216] {taskinstance.py:1357} INFO - Starting attempt 2 of 2
[2022-06-26 13:43:09,216] {taskinstance.py:1358} INFO - 
--------------------------------------------------------------------------------
[2022-06-26 13:43:09,257] {taskinstance.py:1377} INFO - Executing <Task(BashOperator): generate_transaction> on 2022-06-26 13:33:04.519575+00:00
[2022-06-26 13:43:09,266] {standard_task_runner.py:52} INFO - Started process 785 to run task
[2022-06-26 13:43:09,272] {standard_task_runner.py:79} INFO - Running: ['***', 'tasks', 'run', 'fraud_generation', 'generate_transaction', 'scheduled__2022-06-26T13:33:04.519575+00:00', '--job-id', '32', '--raw', '--subdir', 'DAGS_FOLDER/fraud_generation_dag.py', '--cfg-path', '/tmp/tmp8s65akli', '--error-file', '/tmp/tmp881jyayu']
[2022-06-26 13:43:09,279] {standard_task_runner.py:80} INFO - Job 32: Subtask generate_transaction
[2022-06-26 13:43:09,411] {task_command.py:370} INFO - Running <TaskInstance: fraud_generation.generate_transaction scheduled__2022-06-26T13:33:04.519575+00:00 [running]> on host bf947ec15099
[2022-06-26 13:43:09,605] {taskinstance.py:1571} INFO - Exporting the following env vars:
AIRFLOW_CTX_DAG_EMAIL=***@example.com
AIRFLOW_CTX_DAG_OWNER=***
AIRFLOW_CTX_DAG_ID=fraud_generation
AIRFLOW_CTX_TASK_ID=generate_transaction
AIRFLOW_CTX_EXECUTION_DATE=2022-06-26T13:33:04.519575+00:00
AIRFLOW_CTX_TRY_NUMBER=2
AIRFLOW_CTX_DAG_RUN_ID=scheduled__2022-06-26T13:33:04.519575+00:00
[2022-06-26 13:43:09,610] {subprocess.py:62} INFO - Tmp dir root location: 
 /tmp
[2022-06-26 13:43:09,610] {subprocess.py:74} INFO - Running command: ['bash', '-c', 'python script_generation.py 27155']
[2022-06-26 13:43:09,627] {subprocess.py:85} INFO - Output:
[2022-06-26 13:43:09,881] {subprocess.py:92} INFO - python: can't open file 'script_generation.py': [Errno 2] No such file or directory
[2022-06-26 13:43:09,887] {subprocess.py:96} INFO - Command exited with return code 2
[2022-06-26 13:43:09,981] {taskinstance.py:1889} ERROR - Task failed with exception
Traceback (most recent call last):
  File "/home/airflow/.local/lib/python3.7/site-packages/airflow/operators/bash.py", line 195, in execute
    f'Bash command failed. The command returned a non-zero exit code {result.exit_code}.'
airflow.exceptions.AirflowException: Bash command failed. The command returned a non-zero exit code 2.
[2022-06-26 13:43:09,991] {taskinstance.py:1400} INFO - Marking task as FAILED. dag_id=fraud_generation, task_id=generate_transaction, execution_date=20220626T133304, start_date=20220626T134309, end_date=20220626T134309
[2022-06-26 13:43:10,062] {standard_task_runner.py:97} ERROR - Failed to execute job 32 for task generate_transaction (Bash command failed. The command returned a non-zero exit code 2.; 785)
[2022-06-26 13:43:10,105] {local_task_job.py:156} INFO - Task exited with return code 1
[2022-06-26 13:43:10,201] {local_task_job.py:273} INFO - 0 downstream tasks scheduled from follow-on schedule check
