[2022-06-26 14:02:22,014] {taskinstance.py:1159} INFO - Dependencies all met for <TaskInstance: fraud_generation.generate_transaction scheduled__2022-06-26T13:57:18.590703+00:00 [queued]>
[2022-06-26 14:02:22,068] {taskinstance.py:1159} INFO - Dependencies all met for <TaskInstance: fraud_generation.generate_transaction scheduled__2022-06-26T13:57:18.590703+00:00 [queued]>
[2022-06-26 14:02:22,069] {taskinstance.py:1356} INFO - 
--------------------------------------------------------------------------------
[2022-06-26 14:02:22,069] {taskinstance.py:1357} INFO - Starting attempt 1 of 2
[2022-06-26 14:02:22,069] {taskinstance.py:1358} INFO - 
--------------------------------------------------------------------------------
[2022-06-26 14:02:22,170] {taskinstance.py:1377} INFO - Executing <Task(BashOperator): generate_transaction> on 2022-06-26 13:57:18.590703+00:00
[2022-06-26 14:02:22,194] {standard_task_runner.py:52} INFO - Started process 114 to run task
[2022-06-26 14:02:22,214] {standard_task_runner.py:79} INFO - Running: ['***', 'tasks', 'run', 'fraud_generation', 'generate_transaction', 'scheduled__2022-06-26T13:57:18.590703+00:00', '--job-id', '75', '--raw', '--subdir', 'DAGS_FOLDER/fraud_generation_dag.py', '--cfg-path', '/tmp/tmpcj2hhcdd', '--error-file', '/tmp/tmp_973_k3t']
[2022-06-26 14:02:22,219] {standard_task_runner.py:80} INFO - Job 75: Subtask generate_transaction
[2022-06-26 14:02:22,458] {task_command.py:370} INFO - Running <TaskInstance: fraud_generation.generate_transaction scheduled__2022-06-26T13:57:18.590703+00:00 [running]> on host 431a4ea2debb
[2022-06-26 14:02:22,856] {taskinstance.py:1571} INFO - Exporting the following env vars:
AIRFLOW_CTX_DAG_EMAIL=***@example.com
AIRFLOW_CTX_DAG_OWNER=***
AIRFLOW_CTX_DAG_ID=fraud_generation
AIRFLOW_CTX_TASK_ID=generate_transaction
AIRFLOW_CTX_EXECUTION_DATE=2022-06-26T13:57:18.590703+00:00
AIRFLOW_CTX_TRY_NUMBER=1
AIRFLOW_CTX_DAG_RUN_ID=scheduled__2022-06-26T13:57:18.590703+00:00
[2022-06-26 14:02:22,862] {subprocess.py:62} INFO - Tmp dir root location: 
 /tmp
[2022-06-26 14:02:22,863] {subprocess.py:74} INFO - Running command: ['bash', '-c', 'python3 /opt/***/dags/script_generation.py 12914']
[2022-06-26 14:02:22,927] {subprocess.py:85} INFO - Output:
[2022-06-26 14:02:28,722] {subprocess.py:92} INFO - /tmp/***tmp6t2jzx1a
[2022-06-26 14:02:28,729] {subprocess.py:92} INFO - Traceback (most recent call last):
[2022-06-26 14:02:28,730] {subprocess.py:92} INFO -   File "/opt/***/dags/script_generation.py", line 263, in <module>
[2022-06-26 14:02:28,730] {subprocess.py:92} INFO -     main()
[2022-06-26 14:02:28,730] {subprocess.py:92} INFO -   File "/opt/***/dags/script_generation.py", line 252, in main
[2022-06-26 14:02:28,730] {subprocess.py:92} INFO -     subprocess.call(["hdfs", "dfs", "-put", f"{os.path.abspath(full_path)}", f"{file_name}"])
[2022-06-26 14:02:28,730] {subprocess.py:92} INFO -   File "/usr/local/lib/python3.7/subprocess.py", line 339, in call
[2022-06-26 14:02:28,730] {subprocess.py:92} INFO -     with Popen(*popenargs, **kwargs) as p:
[2022-06-26 14:02:28,736] {subprocess.py:92} INFO -   File "/usr/local/lib/python3.7/subprocess.py", line 800, in __init__
[2022-06-26 14:02:28,736] {subprocess.py:92} INFO -     restore_signals, start_new_session)
[2022-06-26 14:02:28,736] {subprocess.py:92} INFO -   File "/usr/local/lib/python3.7/subprocess.py", line 1551, in _execute_child
[2022-06-26 14:02:28,736] {subprocess.py:92} INFO -     raise child_exception_type(errno_num, err_msg, err_filename)
[2022-06-26 14:02:28,736] {subprocess.py:92} INFO - PermissionError: [Errno 13] Permission denied: 'hdfs'
[2022-06-26 14:02:29,293] {subprocess.py:96} INFO - Command exited with return code 1
[2022-06-26 14:02:29,375] {taskinstance.py:1889} ERROR - Task failed with exception
Traceback (most recent call last):
  File "/home/airflow/.local/lib/python3.7/site-packages/airflow/operators/bash.py", line 195, in execute
    f'Bash command failed. The command returned a non-zero exit code {result.exit_code}.'
airflow.exceptions.AirflowException: Bash command failed. The command returned a non-zero exit code 1.
[2022-06-26 14:02:29,386] {taskinstance.py:1400} INFO - Marking task as UP_FOR_RETRY. dag_id=fraud_generation, task_id=generate_transaction, execution_date=20220626T135718, start_date=20220626T140222, end_date=20220626T140229
[2022-06-26 14:02:29,457] {standard_task_runner.py:97} ERROR - Failed to execute job 75 for task generate_transaction (Bash command failed. The command returned a non-zero exit code 1.; 114)
[2022-06-26 14:02:29,531] {local_task_job.py:156} INFO - Task exited with return code 1
[2022-06-26 14:02:29,722] {local_task_job.py:273} INFO - 0 downstream tasks scheduled from follow-on schedule check
