[2022-06-26 13:38:34,033] {taskinstance.py:1159} INFO - Dependencies all met for <TaskInstance: fraud_generation.generate_transaction scheduled__2022-06-26T13:33:31.825487+00:00 [queued]>
[2022-06-26 13:38:34,076] {taskinstance.py:1159} INFO - Dependencies all met for <TaskInstance: fraud_generation.generate_transaction scheduled__2022-06-26T13:33:31.825487+00:00 [queued]>
[2022-06-26 13:38:34,077] {taskinstance.py:1356} INFO - 
--------------------------------------------------------------------------------
[2022-06-26 13:38:34,077] {taskinstance.py:1357} INFO - Starting attempt 1 of 2
[2022-06-26 13:38:34,077] {taskinstance.py:1358} INFO - 
--------------------------------------------------------------------------------
[2022-06-26 13:38:34,136] {taskinstance.py:1377} INFO - Executing <Task(BashOperator): generate_transaction> on 2022-06-26 13:33:31.825487+00:00
[2022-06-26 13:38:34,152] {standard_task_runner.py:52} INFO - Started process 591 to run task
[2022-06-26 13:38:34,166] {standard_task_runner.py:79} INFO - Running: ['***', 'tasks', 'run', 'fraud_generation', 'generate_transaction', 'scheduled__2022-06-26T13:33:31.825487+00:00', '--job-id', '31', '--raw', '--subdir', 'DAGS_FOLDER/fraud_generation_dag.py', '--cfg-path', '/tmp/tmpl7_o8_c2', '--error-file', '/tmp/tmpua3aer3s']
[2022-06-26 13:38:34,166] {standard_task_runner.py:80} INFO - Job 31: Subtask generate_transaction
[2022-06-26 13:38:34,281] {task_command.py:370} INFO - Running <TaskInstance: fraud_generation.generate_transaction scheduled__2022-06-26T13:33:31.825487+00:00 [running]> on host bf947ec15099
[2022-06-26 13:38:34,482] {taskinstance.py:1571} INFO - Exporting the following env vars:
AIRFLOW_CTX_DAG_EMAIL=***@example.com
AIRFLOW_CTX_DAG_OWNER=***
AIRFLOW_CTX_DAG_ID=fraud_generation
AIRFLOW_CTX_TASK_ID=generate_transaction
AIRFLOW_CTX_EXECUTION_DATE=2022-06-26T13:33:31.825487+00:00
AIRFLOW_CTX_TRY_NUMBER=1
AIRFLOW_CTX_DAG_RUN_ID=scheduled__2022-06-26T13:33:31.825487+00:00
[2022-06-26 13:38:34,483] {subprocess.py:62} INFO - Tmp dir root location: 
 /tmp
[2022-06-26 13:38:34,484] {subprocess.py:74} INFO - Running command: ['bash', '-c', 'python script_generation.py 1298']
[2022-06-26 13:38:34,512] {subprocess.py:85} INFO - Output:
[2022-06-26 13:38:34,686] {subprocess.py:92} INFO - python: can't open file 'script_generation.py': [Errno 2] No such file or directory
[2022-06-26 13:38:34,691] {subprocess.py:96} INFO - Command exited with return code 2
[2022-06-26 13:38:34,739] {taskinstance.py:1889} ERROR - Task failed with exception
Traceback (most recent call last):
  File "/home/airflow/.local/lib/python3.7/site-packages/airflow/operators/bash.py", line 195, in execute
    f'Bash command failed. The command returned a non-zero exit code {result.exit_code}.'
airflow.exceptions.AirflowException: Bash command failed. The command returned a non-zero exit code 2.
[2022-06-26 13:38:34,744] {taskinstance.py:1400} INFO - Marking task as UP_FOR_RETRY. dag_id=fraud_generation, task_id=generate_transaction, execution_date=20220626T133331, start_date=20220626T133834, end_date=20220626T133834
[2022-06-26 13:38:34,775] {standard_task_runner.py:97} ERROR - Failed to execute job 31 for task generate_transaction (Bash command failed. The command returned a non-zero exit code 2.; 591)
[2022-06-26 13:38:34,802] {local_task_job.py:156} INFO - Task exited with return code 1
[2022-06-26 13:38:34,857] {local_task_job.py:273} INFO - 0 downstream tasks scheduled from follow-on schedule check
