[2022-06-26 13:56:08,218] {taskinstance.py:1159} INFO - Dependencies all met for <TaskInstance: fraud_generation.generate_transaction scheduled__2022-06-26T13:33:31.825487+00:00 [queued]>
[2022-06-26 13:56:08,277] {taskinstance.py:1159} INFO - Dependencies all met for <TaskInstance: fraud_generation.generate_transaction scheduled__2022-06-26T13:33:31.825487+00:00 [queued]>
[2022-06-26 13:56:08,277] {taskinstance.py:1356} INFO - 
--------------------------------------------------------------------------------
[2022-06-26 13:56:08,277] {taskinstance.py:1357} INFO - Starting attempt 2 of 2
[2022-06-26 13:56:08,277] {taskinstance.py:1358} INFO - 
--------------------------------------------------------------------------------
[2022-06-26 13:56:08,505] {taskinstance.py:1377} INFO - Executing <Task(BashOperator): generate_transaction> on 2022-06-26 13:33:31.825487+00:00
[2022-06-26 13:56:08,520] {standard_task_runner.py:52} INFO - Started process 98 to run task
[2022-06-26 13:56:08,541] {standard_task_runner.py:79} INFO - Running: ['***', 'tasks', 'run', 'fraud_generation', 'generate_transaction', 'scheduled__2022-06-26T13:33:31.825487+00:00', '--job-id', '36', '--raw', '--subdir', 'DAGS_FOLDER/fraud_generation_dag.py', '--cfg-path', '/tmp/tmp7fbky0xd', '--error-file', '/tmp/tmpugjtqjxe']
[2022-06-26 13:56:08,557] {standard_task_runner.py:80} INFO - Job 36: Subtask generate_transaction
[2022-06-26 13:56:08,932] {task_command.py:370} INFO - Running <TaskInstance: fraud_generation.generate_transaction scheduled__2022-06-26T13:33:31.825487+00:00 [running]> on host 431a4ea2debb
[2022-06-26 13:56:09,382] {taskinstance.py:1571} INFO - Exporting the following env vars:
AIRFLOW_CTX_DAG_EMAIL=***@example.com
AIRFLOW_CTX_DAG_OWNER=***
AIRFLOW_CTX_DAG_ID=fraud_generation
AIRFLOW_CTX_TASK_ID=generate_transaction
AIRFLOW_CTX_EXECUTION_DATE=2022-06-26T13:33:31.825487+00:00
AIRFLOW_CTX_TRY_NUMBER=2
AIRFLOW_CTX_DAG_RUN_ID=scheduled__2022-06-26T13:33:31.825487+00:00
[2022-06-26 13:56:09,385] {subprocess.py:62} INFO - Tmp dir root location: 
 /tmp
[2022-06-26 13:56:09,386] {subprocess.py:74} INFO - Running command: ['bash', '-c', 'python3 /opt/***/dags/script_generation.py 3395']
[2022-06-26 13:56:09,455] {subprocess.py:85} INFO - Output:
[2022-06-26 13:56:13,960] {subprocess.py:92} INFO - Traceback (most recent call last):
[2022-06-26 13:56:13,961] {subprocess.py:92} INFO -   File "/opt/***/dags/script_generation.py", line 263, in <module>
[2022-06-26 13:56:13,961] {subprocess.py:92} INFO -     main()
[2022-06-26 13:56:13,961] {subprocess.py:92} INFO -   File "/opt/***/dags/script_generation.py", line 230, in main
[2022-06-26 13:56:13,961] {subprocess.py:92} INFO -     os.mkdirs(DIR_OUTPUT, exist_ok=True)
[2022-06-26 13:56:13,961] {subprocess.py:92} INFO - AttributeError: module 'os' has no attribute 'mkdirs'
[2022-06-26 13:56:14,785] {subprocess.py:96} INFO - Command exited with return code 1
[2022-06-26 13:56:14,898] {taskinstance.py:1889} ERROR - Task failed with exception
Traceback (most recent call last):
  File "/home/airflow/.local/lib/python3.7/site-packages/airflow/operators/bash.py", line 195, in execute
    f'Bash command failed. The command returned a non-zero exit code {result.exit_code}.'
airflow.exceptions.AirflowException: Bash command failed. The command returned a non-zero exit code 1.
[2022-06-26 13:56:14,972] {taskinstance.py:1400} INFO - Marking task as FAILED. dag_id=fraud_generation, task_id=generate_transaction, execution_date=20220626T133331, start_date=20220626T135608, end_date=20220626T135614
[2022-06-26 13:56:15,185] {standard_task_runner.py:97} ERROR - Failed to execute job 36 for task generate_transaction (Bash command failed. The command returned a non-zero exit code 1.; 98)
[2022-06-26 13:56:15,364] {local_task_job.py:156} INFO - Task exited with return code 1
[2022-06-26 13:56:15,544] {local_task_job.py:273} INFO - 0 downstream tasks scheduled from follow-on schedule check
