[2022-09-14 19:57:04,704] {taskinstance.py:1179} INFO - Dependencies all met for <TaskInstance: preprocessing_data.clean_data manual__2022-09-14T14:54:44.164850+00:00 [queued]>
[2022-09-14 19:57:04,710] {taskinstance.py:1179} INFO - Dependencies all met for <TaskInstance: preprocessing_data.clean_data manual__2022-09-14T14:54:44.164850+00:00 [queued]>
[2022-09-14 19:57:04,710] {taskinstance.py:1376} INFO - 
--------------------------------------------------------------------------------
[2022-09-14 19:57:04,710] {taskinstance.py:1377} INFO - Starting attempt 1 of 2
[2022-09-14 19:57:04,710] {taskinstance.py:1378} INFO - 
--------------------------------------------------------------------------------
[2022-09-14 19:57:04,723] {taskinstance.py:1397} INFO - Executing <Task(PythonOperator): clean_data> on 2022-09-14 14:54:44.164850+00:00
[2022-09-14 19:57:04,728] {standard_task_runner.py:52} INFO - Started process 23539 to run task
[2022-09-14 19:57:04,731] {standard_task_runner.py:79} INFO - Running: ['airflow', 'tasks', 'run', 'preprocessing_data', 'clean_data', 'manual__2022-09-14T14:54:44.164850+00:00', '--job-id', '204', '--raw', '--subdir', 'DAGS_FOLDER/model_dag.py', '--cfg-path', '/tmp/tmp5d1h589x', '--error-file', '/tmp/tmptecbyazm']
[2022-09-14 19:57:04,732] {standard_task_runner.py:80} INFO - Job 204: Subtask clean_data
[2022-09-14 19:57:04,778] {task_command.py:371} INFO - Running <TaskInstance: preprocessing_data.clean_data manual__2022-09-14T14:54:44.164850+00:00 [running]> on host rc1b-dataproc-m-xzxwmqcudfo0foh0.mdb.yandexcloud.net
[2022-09-14 19:57:04,825] {taskinstance.py:1589} INFO - Exporting the following env vars:
AIRFLOW_CTX_DAG_EMAIL=airflow@example.com
AIRFLOW_CTX_DAG_OWNER=airflow
AIRFLOW_CTX_DAG_ID=preprocessing_data
AIRFLOW_CTX_TASK_ID=clean_data
AIRFLOW_CTX_EXECUTION_DATE=2022-09-14T14:54:44.164850+00:00
AIRFLOW_CTX_TRY_NUMBER=1
AIRFLOW_CTX_DAG_RUN_ID=manual__2022-09-14T14:54:44.164850+00:00
[2022-09-14 19:57:21,923] {taskinstance.py:1909} ERROR - Task failed with exception
Traceback (most recent call last):
  File "/home/ubuntu/.local/lib/python3.8/site-packages/airflow/operators/python.py", line 171, in execute
    return_value = self.execute_callable()
  File "/home/ubuntu/.local/lib/python3.8/site-packages/airflow/operators/python.py", line 189, in execute_callable
    return self.python_callable(*self.op_args, **self.op_kwargs)
  File "/home/ubuntu/fraud-detection-ml/utils/pyspark_cleaning.py", line 84, in clean_data
    result = pipeline.fit(df).transform(df).select("featuresFinal", "TX_FRAUD")
  File "/usr/lib/spark/python/pyspark/ml/base.py", line 129, in fit
    return self._fit(dataset)
  File "/usr/lib/spark/python/pyspark/ml/pipeline.py", line 96, in _fit
    raise TypeError(
TypeError: Cannot recognize a pipeline stage of type <class 'list'>.
[2022-09-14 19:57:21,928] {taskinstance.py:1415} INFO - Marking task as UP_FOR_RETRY. dag_id=preprocessing_data, task_id=clean_data, execution_date=20220914T145444, start_date=20220914T195704, end_date=20220914T195721
[2022-09-14 19:57:21,945] {standard_task_runner.py:92} ERROR - Failed to execute job 204 for task clean_data (Cannot recognize a pipeline stage of type <class 'list'>.; 23539)
[2022-09-14 19:57:21,974] {local_task_job.py:156} INFO - Task exited with return code 1
[2022-09-14 19:57:21,994] {local_task_job.py:273} INFO - 0 downstream tasks scheduled from follow-on schedule check
