[2022-06-26 14:17:49,581] {taskinstance.py:1159} INFO - Dependencies all met for <TaskInstance: fraud_generation.generate_transaction scheduled__2022-06-26T14:12:47.607753+00:00 [queued]>
[2022-06-26 14:17:49,597] {taskinstance.py:1159} INFO - Dependencies all met for <TaskInstance: fraud_generation.generate_transaction scheduled__2022-06-26T14:12:47.607753+00:00 [queued]>
[2022-06-26 14:17:49,597] {taskinstance.py:1356} INFO - 
--------------------------------------------------------------------------------
[2022-06-26 14:17:49,598] {taskinstance.py:1357} INFO - Starting attempt 1 of 2
[2022-06-26 14:17:49,598] {taskinstance.py:1358} INFO - 
--------------------------------------------------------------------------------
[2022-06-26 14:17:49,630] {taskinstance.py:1377} INFO - Executing <Task(BashOperator): generate_transaction> on 2022-06-26 14:12:47.607753+00:00
[2022-06-26 14:17:49,638] {standard_task_runner.py:52} INFO - Started process 963 to run task
[2022-06-26 14:17:49,649] {standard_task_runner.py:79} INFO - Running: ['***', 'tasks', 'run', 'fraud_generation', 'generate_transaction', 'scheduled__2022-06-26T14:12:47.607753+00:00', '--job-id', '93', '--raw', '--subdir', 'DAGS_FOLDER/fraud_generation_dag.py', '--cfg-path', '/tmp/tmppadachwf', '--error-file', '/tmp/tmpnh0x2gbi']
[2022-06-26 14:17:49,651] {standard_task_runner.py:80} INFO - Job 93: Subtask generate_transaction
[2022-06-26 14:17:49,755] {task_command.py:370} INFO - Running <TaskInstance: fraud_generation.generate_transaction scheduled__2022-06-26T14:12:47.607753+00:00 [running]> on host 431a4ea2debb
[2022-06-26 14:17:49,890] {taskinstance.py:1571} INFO - Exporting the following env vars:
AIRFLOW_CTX_DAG_EMAIL=***@example.com
AIRFLOW_CTX_DAG_OWNER=***
AIRFLOW_CTX_DAG_ID=fraud_generation
AIRFLOW_CTX_TASK_ID=generate_transaction
AIRFLOW_CTX_EXECUTION_DATE=2022-06-26T14:12:47.607753+00:00
AIRFLOW_CTX_TRY_NUMBER=1
AIRFLOW_CTX_DAG_RUN_ID=scheduled__2022-06-26T14:12:47.607753+00:00
[2022-06-26 14:17:49,892] {subprocess.py:62} INFO - Tmp dir root location: 
 /tmp
[2022-06-26 14:17:49,896] {subprocess.py:74} INFO - Running command: ['bash', '-c', 'python3 /opt/***/dags/script_generation.py 4581']
[2022-06-26 14:17:49,915] {subprocess.py:85} INFO - Output:
[2022-06-26 14:17:51,035] {subprocess.py:92} INFO - /tmp/***tmpiohnnrp5
[2022-06-26 14:17:51,036] {subprocess.py:92} INFO - Traceback (most recent call last):
[2022-06-26 14:17:51,037] {subprocess.py:92} INFO -   File "/opt/***/dags/script_generation.py", line 263, in <module>
[2022-06-26 14:17:51,037] {subprocess.py:92} INFO -     main()
[2022-06-26 14:17:51,037] {subprocess.py:92} INFO -   File "/opt/***/dags/script_generation.py", line 252, in main
[2022-06-26 14:17:51,037] {subprocess.py:92} INFO -     subprocess.call(["hdfs", "dfs", "-put", f"{os.path.abspath(full_path)}", f"{file_name}"])
[2022-06-26 14:17:51,037] {subprocess.py:92} INFO -   File "/usr/local/lib/python3.7/subprocess.py", line 339, in call
[2022-06-26 14:17:51,037] {subprocess.py:92} INFO -     with Popen(*popenargs, **kwargs) as p:
[2022-06-26 14:17:51,037] {subprocess.py:92} INFO -   File "/usr/local/lib/python3.7/subprocess.py", line 800, in __init__
[2022-06-26 14:17:51,037] {subprocess.py:92} INFO -     restore_signals, start_new_session)
[2022-06-26 14:17:51,037] {subprocess.py:92} INFO -   File "/usr/local/lib/python3.7/subprocess.py", line 1551, in _execute_child
[2022-06-26 14:17:51,037] {subprocess.py:92} INFO -     raise child_exception_type(errno_num, err_msg, err_filename)
[2022-06-26 14:17:51,037] {subprocess.py:92} INFO - PermissionError: [Errno 13] Permission denied: 'hdfs'
[2022-06-26 14:17:51,102] {subprocess.py:96} INFO - Command exited with return code 1
[2022-06-26 14:17:51,120] {taskinstance.py:1889} ERROR - Task failed with exception
Traceback (most recent call last):
  File "/home/airflow/.local/lib/python3.7/site-packages/airflow/operators/bash.py", line 195, in execute
    f'Bash command failed. The command returned a non-zero exit code {result.exit_code}.'
airflow.exceptions.AirflowException: Bash command failed. The command returned a non-zero exit code 1.
[2022-06-26 14:17:51,123] {taskinstance.py:1400} INFO - Marking task as UP_FOR_RETRY. dag_id=fraud_generation, task_id=generate_transaction, execution_date=20220626T141247, start_date=20220626T141749, end_date=20220626T141751
[2022-06-26 14:17:51,137] {standard_task_runner.py:97} ERROR - Failed to execute job 93 for task generate_transaction (Bash command failed. The command returned a non-zero exit code 1.; 963)
[2022-06-26 14:17:51,156] {local_task_job.py:156} INFO - Task exited with return code 1
[2022-06-26 14:17:51,193] {local_task_job.py:273} INFO - 0 downstream tasks scheduled from follow-on schedule check
